Workbook

Sheet README
A1: Retirement plan
A2: A year-by-year retirement model for a couple, with a Monte Carlo test against history. See the project README for how to use it with Claude.
A4: Tabs
A5: Model - ...: a scenario. Yellow cells are its inputs (when you stop working, pensions, property sales, one-off events). Duplicate the tab to try another scenario.
A6: household: names, birth years, CPP and OAS, kids.
A7: budget: 12 months of spending by category (the statement pipeline fills it). The retirement_budget column is what the model spends.
A8: kids_budget: one line per kid and cost (support, college, help after college), each with its own years and amount.
A9: other_budget: renovations, cars and other big irregular costs, per year.
A10: properties: your home and any other properties.
A11: healthcare: private health/dental plan, out-of-pocket and long-term care costs.
A12: assets: every account, its balance and which bucket it feeds.
A13: tax_tables: the tax law the model uses (federal + your province). Edit to change state/province or update the law.
... A24: Not financial advice. Tax rules are simplified; check important decisions with a professional.

Sheet Model - Example
A1: Retirement model - Example
A2: Yellow cells are this scenario's inputs. To try another scenario: right-click this tab > Duplicate, rename it 'Model - <name>', change its yellow cells. Shared facts (budgets, properties, accounts, healthcare, tax law) are on the other tabs. Don't insert or delete rows on this tab.
A4: WORK | E4: RESULTS (today's dollars)
A5: =household!$B$5&"'s first year without a paycheck" | B5: 2030 | C5: The year after the last working year | E5: ="Net worth when "&household!$B$5&" is 70" | G5: =IFERROR(INDEX($J$81:$J$123,MATCH(household!$B$6+70,$A$81:$A$123,0)),"")
A6: =household!$B$8&"'s first year without a paycheck" | B6: 2031 | E6: ... at 80 | G6: =IFERROR(INDEX($J$81:$J$123,MATCH(household!$B$6+80,$A$81:$A$123,0)),"")
A7: =household!$B$5&"'s pay per year while working (today's $)" | B7: 165000 | C7: Salary + bonus + stock vesting | E7: ... at 85 | G7: =IFERROR(INDEX($J$81:$J$123,MATCH(household!$B$6+85,$A$81:$A$123,0)),"")
A8: =household!$B$8&"'s pay per year while working" | B8: 112000 | E8: ... at 90 | G8: =IFERROR(INDEX($J$81:$J$123,MATCH(household!$B$6+90,$A$81:$A$123,0)),"")
A9: =household!$B$5&"'s RRSP / pension contributions" | B9: 16000 | C9: While working | E9: ... at 95 | G9: =IFERROR(INDEX($J$81:$J$123,MATCH(household!$B$6+95,$A$81:$A$123,0)),"")
A10: =household!$B$8&"'s RRSP / pension contributions" | B10: 11000 | E10: ="Investments when "&household!$B$5&" is 90" | G10: =IFERROR(MAX(0,INDEX($I$81:$I$123,MATCH(household!$B$6+90,$A$81:$A$123,0))),"")
A11: ="Employer match / pension contributions for "&household!$B$5 | B11: 8000 | E11: First year investments can't cover costs | G11: =IF(COUNTIF($K$81:$K$123,">1")=0,"never",SUMPRODUCT(MIN($A$81:$A$123+($K$81:$K$123<=1)*10000)))
A12: ="Employer match / pension contributions for "&household!$B$8 | B12: 5500 | E12: First year's living costs | G12: =INDEX($D$81:$D$123,1)
A13: Income tax withheld from pay | B13: 0.27 | C13: Share of taxable pay; the difference is settled next April | E13: First year's withdrawal rate | G13: =INDEX($H$81:$H$123,1)
A14: Tax owed for last year, paid in April of the first year | B14: 0 | C14: Negative = a refund | E14: Lifetime income tax (today's $) | G14: =SUMPRODUCT($EC$81:$EC$123/$O$81:$O$123)
A16: ECONOMY
A17: Inflation | B17: 0.025 | C17: Living costs, pay, pensions, tax brackets
A18: Investment return (per year, before inflation) | B18: 0.05 | C18: Override any year in the yellow 'Return override' column below
A19: Dividend yield on non-registered accounts | B19: 0.025 | C19: Paid out as cash each year
A20: Share of those dividends that are eligible Canadian dividends | B20: 0.5 | C20: The rest (foreign, interest) is taxed as ordinary income
A21: Healthcare cost growth | B21: =healthcare!$B$5 | C21: From the healthcare tab
A22: College cost growth | B22: 0.035
A23: Long-term care cost growth | B23: =healthcare!$B$7 | C23: From the healthcare tab
A25: CPP AND OAS
A26: =household!$B$5&" starts CPP at age" | B26: 70 | C26: 60-70: -0.6%/month before 65, +0.7%/month after
A27: =household!$B$8&" starts CPP at age" | B27: 65
A28: =household!$B$5&" starts OAS at age" | B28: 67 | C28: 65-70: +0.6%/month deferred
A29: =household!$B$8&" starts OAS at age" | B29: 65
A30: =household!$B$5&"'s CPP vs age 65" | B30: =IF(ROUND(($B$26-65)*12,0)>=0,1+0.007*MIN(ROUND(($B$26-65)*12,0),60),1+0.006*MAX(ROUND(($B$26-65)*12,0),-60))
A31: =household!$B$8&"'s CPP vs age 65" | B31: =IF(ROUND(($B$27-65)*12,0)>=0,1+0.007*MIN(ROUND(($B$27-65)*12,0),60),1+0.006*MAX(ROUND(($B$27-65)*12,0),-60))
A32: =household!$B$5&"'s OAS deferral increase" | B32: =1+0.006*MIN(60,MAX(0,ROUND(($B$28-65)*12,0)))
A33: =household!$B$8&"'s OAS deferral increase" | B33: =1+0.006*MIN(60,MAX(0,ROUND(($B$29-65)*12,0)))
A35: WORKPLACE PENSIONS
A36: =household!$B$5&"'s defined-benefit pension per year (today's $)" | B36: 0 | C36: 0 = none. Your pension statement's estimate
A37: ... starts at age | B37: 65
A38: =household!$B$8&"'s defined-benefit pension per year (today's $)" | B38: 30000
A39: ... starts at age | B39: 65
A40: Pension increases, as a share of inflation | B40: 0.8 | C40: 0% = fixed dollar amount, 100% = fully indexed
A41: Share that continues to the survivor | B41: 0.6 | C41: Joint-and-survivor option; used in the Monte Carlo's lifetime runs
A43: HEALTHCARE AND LONG-TERM CARE
A44: =household!$B$5&" needs long-term care from age" | B44: 85 | C44: Paid from savings
A45: ... for this many years | B45: 2 | C45: Averages: men ~2 years, women ~3.5
...

Sheet household
A1: key | B1: value | C1: notes
A2: country | B2: CA | C2: US = United States, CA = Canada. Fixed when the workbook is built
A3: region | B3: British Columbia | C3: State or province (its tax brackets are on the tax_tables tab)
A4: start_year | B4: 2027 | C4: First year the model covers. Balances on the assets tab are as of 1 January of it; 'today's dollars' are the year before
A5: p1_name | B5: Sam | C5: Person 1
A6: p1_born | B6: 1967 | C6: Birth year
A7: p1_sex | B7: M | C7: M or F: which column of the life table the Monte Carlo uses for person 1
A8: p2_name | B8: Taylor | C8: Person 2
A9: p2_born | B9: 1969 | C9: Birth year
A10: p2_sex | B10: F | C10: M or F for person 2
A11: p1_cpp_at_65 | B11: 1320 | C11: Person 1's CPP at 65, per month, today's $ - from My Service Canada Account
A12: p2_cpp_at_65 | B12: 1040 | C12: Person 2's CPP at 65
A13: p1_oas_years | B13: 40 | C13: Person 1's years in Canada after 18 (40 = full OAS)
A14: p2_oas_years | B14: 34 | C14: Person 2's years in Canada after 18
A15: joint_share_p1 | B15: 0.5 | C15: Share of joint investment and rental income taxed to person 1 (usually 50%)
A16: tfsa_room | B16: 42000 | C16: Unused TFSA room for the two of you on 1 January of the first year (incl. that year's new room)
A18: Kids
A19: name | B19: born | C19: (not used) | D19: notes
A20: Morgan | B20: 2007 | D20: At UBC
A21: Jamie | B21: 2010 | D21: Starts university in 2028
A28: Kids' costs are on the kids_budget tab (one line per kid and cost).

Sheet budget
A1: model_line | B1: expense_group | C1: category | D1: subcategory | E1: annual_actual | F1: retirement_budget | G1: source_period | H1: n_transactions | I1: notes | K1: Household living budget used by the model | L1: =SUMIF($A$2:$A$300,"household",$F$2:$F$300)
A2: household | B2: Essential | C2: Groceries | D2: General | E2: 17200 | F2: 17200 | G2: example | H2: 230 | K2: All lines, 12-month actual | L2: =SUM($E$2:$E$300)
A3: household | B3: Essential | C3: Utilities | D3: Electric, gas, water | E3: 2600 | F3: 2600 | G3: example | H3: 12
A4: household | B4: Essential | C4: Utilities | D4: Phone & internet | E4: 2900 | F4: 2900 | G4: example | H4: 24 | K4: model_line: 'household' lines are summed and grow with inflation. Other lines (housing, healthcare, taxes, kids) are modeled on their own tabs and shown here only for reference.
A5: household | B5: Essential | C5: Insurance | D5: General | E5: 3800 | F5: 3800 | G5: example | H5: 4 | K5: Edit column F (retirement_budget) to test a different budget; column E is what you actually spent.
A6: household | B6: Essential | C6: Transportation | D6: Gas & parking | E6: 4200 | F6: 4200 | G6: example | H6: 120
A7: household | B7: Essential | C7: Transportation | D7: Car maintenance | E7: 1600 | F7: 1600 | G7: example | H7: 4
A8: household | B8: Essential | C8: Personal Care | D8: General | E8: 1900 | F8: 1900 | G8: example | H8: 28
A9: household | B9: Discretionary | C9: Dining | D9: Restaurants & takeout | E9: 8900 | F9: 8900 | G9: example | H9: 170
A10: household | B10: Discretionary | C10: Travel | D10: Flights, hotels, rentals | E10: 13000 | F10: 15000 | G10: example | H10: 32 | I10: More travel once retired
A11: household | B11: Discretionary | C11: Shopping | D11: General | E11: 9400 | F11: 9000 | G11: example | H11: 210
A12: household | B12: Discretionary | C12: Entertainment | D12: General | E12: 2800 | F12: 2800 | G12: example | H12: 40
A13: household | B13: Discretionary | C13: Subscriptions | D13: Streaming & software | E13: 1100 | F13: 1100 | G13: example | H13: 44
A14: household | B14: Discretionary | C14: Gifts & Donations | D14: General | E14: 4200 | F14: 4200 | G14: example | H14: 20
A15: household | B15: Discretionary | C15: Home | D15: Household goods | E15: 2600 | F15: 2600 | G15: example | H15: 40
A16: household | B16: Discretionary | C16: Recreation | D16: Gym, sports | E16: 3500 | F16: 3500 | G16: example | H16: 12
A17: housing | B17: Housing | C17: Housing | D17: Mortgage | E17: 36400 | G17: example | H17: 26 | I17: Modeled from the properties tab
A18: housing | B18: Housing | C18: Housing | D18: Property tax, strata, insurance | E18: 11800 | G18: example | H18: 16 | I18: Modeled from the properties tab (carrying_costs)
A19: healthcare | B19: Healthcare | C19: Healthcare | D19: Dental, drugs, physio | E19: 2900 | G19: example | H19: 30 | I19: Modeled on the healthcare tab
A20: kids | B20: Kids | C20: Kids | D20: Support | E20: 14400 | G20: example | H20: 40 | I20: Modeled on the kids_budget tab

Sheet kids_budget
A1: kid | B1: item | C1: annual_amount_today | D1: start_year | E1: end_year | F1: inflation | G1: paid_from | H1: notes
A2: Morgan | B2: UBC tuition + books | C2: 9500 | D2: 2027 | E2: 2029 | F2: college | G2: college_funds | H2: RESP pays first
A3: Morgan | B3: Living at home - extra costs | C3: 6000 | D3: 2027 | E3: 2029 | F3: general | G3: parents
A4: Morgan | B4: Help after graduating (rent share) | C4: 12000 | D4: 2030 | E4: 2032 | F4: general | G4: parents | H4: Vancouver rents
A5: Jamie | B5: University tuition + residence (out of town) | C5: 24000 | D5: 2028 | E5: 2031 | F5: college | G5: college_funds
A6: Jamie | B6: Spending money | C6: 4800 | D6: 2028 | E6: 2031 | F6: general | G6: parents
A7: Jamie | B7: Help after graduating | C7: 9000 | D7: 2032 | E7: 2033 | F7: general | G7: parents
A8: Jamie | B8: Master's degree | C8: 18000 | D8: 2034 | E8: 2035 | F8: college | G8: parents
A42: One line per kid and cost, per year in today's dollars, for the years start_year-end_year. inflation: 'college' lines rise with college cost growth, 'general' with inflation. paid_from: 'college_funds' lines are paid by the RESPs first and only the shortfall comes from you; 'parents' lines come straight from you. Add rows above row 41.

Sheet other_budget
A1: item | B1: annual_amount_today | C1: start_year | D1: end_year | E1: notes
A2: Home maintenance and renovations | B2: 10000 | C2: 2027 | D2: 2060
A3: Car replacement | B3: 7000 | C3: 2027 | D3: 2055
A4: Cabin trips / cottage share | B4: 3000 | C4: 2027 | D4: 2045
A32: Big irregular costs averaged per year (renovations, cars, gifts), in today's dollars, for the years start_year-end_year. Add rows above row 31.

Sheet properties
A1: property | B1: type | C1: value_now | D1: appreciation | E1: selling_cost_pct | F1: cost_basis | G1: carrying_costs | H1: property_tax | I1: mortgage_balance | J1: mortgage_rate | K1: mortgage_payment | L1: rent | M1: cash_costs | N1: depreciation | O1: depreciation_end_year | P1: accum_depreciation | Q1: notes
A2: House (East Vancouver) | B2: primary | C2: 1850000 | D2: 0.03 | E2: 0.04 | F2: 780000 | G2: 11800 | H2: 6300 | I2: 340000 | J2: 0.0449 | K2: 36400 | Q2: Principal residence: the gain on sale isn't taxed. Carrying costs: property tax $6,300, insurance $3,000, utilities/other $2,500
A3: Condo rental (Burnaby) | B3: rental | C3: 720000 | D3: 0.025 | E3: 0.045 | F3: 540000 | L3: 32400 | M3: 11800 | N3: 9500 | O3: 2045 | P3: 48000 | Q3: Bought 2019 for $540,000. Cash costs: strata $4,600, property tax $2,400, insurance $900, repairs $1,400, vacancy tax/other $2,500. CCA claimed yearly
A9: Row 2 is your home (principal residence); rows 3-6 are other properties (rentals, a cottage). Sell / rent decisions are made on each Model tab. Amounts are today's dollars.
A10: value_now: market value; appreciation: growth per year. carrying_costs: property tax + condo/HOA/strata fees + insurance + utilities you want counted as housing (for the home; if you rent, put the rent here and leave value_now blank). property_tax: the part that's property tax (not used in Canada).
A11: mortgage_*: the home's mortgage on 1 January of the first year (balance, interest rate, payments per year). Other properties are assumed mortgage-free: include any loan payments in cash_costs.
A12: Other properties: rent and cash_costs per year; depreciation (capital cost allowance) claimed per year until depreciation_end_year, and accum_depreciation already claimed. cost_basis is what you paid plus improvements.

Sheet healthcare
A1: key | B1: value | C1: unit | D1: notes | E1: source
A2: employer_plan_cost | B2: 1500 | C2: $/year | D2: Your share of the group benefits plan + out-of-pocket while working | E2: Benefits statement
A3: private_plan_monthly | B3: 160 | C3: $/month | D3: Extended health + dental for one retired adult (e.g. PacificBlue Cross, Manulife FlexCare) | E3: Insurer quotes
A4: oop_per_person | B4: 1800 | C4: $/year | D4: Drugs above PharmaCare, dental, vision, physio not covered
A5: medical_inflation | B5: 0.045 | C5: per year
A6: ltc_annual_cost | B6: 95000 | C6: $/year | D6: Private assisted living / private-pay care in Metro Vancouver. Publicly subsidized long-term care costs up to 80% of after-tax income instead | E6: BC Seniors Advocate
A7: ltc_inflation | B7: 0.04 | C7: per year

Sheet assets
A1: account | B1: bucket | C1: value | D1: as_of | E1: cost_basis | F1: notes | H1: bucket | I1: total | J1: cost basis | K1: what goes in it
A2: Joint non-registered (ETFs) | B2: non_registered | C2: 420000 | D2: 2027-01-01 | E2: 290000 | F2: Adjusted cost base from the broker | H2: non_registered | I2: =SUMIF($B$2:$B$150,"non_registered",$C$2:$C$150) | J2: =SUMIF($B$2:$B$150,"non_registered",$E$2:$E$150) | K2: Non-registered investment accounts, bank and savings cash
A3: High-interest savings | B3: non_registered | C3: 35000 | D3: 2027-01-01 | F3: cash: cost basis = value | H3: rrsp_p1 | I3: =SUMIF($B$2:$B$150,"rrsp_p1",$C$2:$C$150) | K3: Person 1's RRSP, RRIF, LIRA, defined-contribution pension
A4: Chequing | B4: non_registered | C4: 12000 | D4: 2027-01-01 | H4: rrsp_p2 | I4: =SUMIF($B$2:$B$150,"rrsp_p2",$C$2:$C$150) | K4: Person 2's RRSP/RRIF/LIRA
A5: Sam RRSP | B5: rrsp_p1 | C5: 760000 | D5: 2027-01-01 | H5: tfsa | I5: =SUMIF($B$2:$B$150,"tfsa",$C$2:$C$150) | K5: TFSAs (either person)
A6: Sam DC pension (LIRA on leaving) | B6: rrsp_p1 | C6: 180000 | D6: 2027-01-01 | H6: resp | I6: =SUMIF($B$2:$B$150,"resp",$C$2:$C$150) | K6: RESPs (the kids' education money; not counted as yours)
A7: Taylor RRSP | B7: rrsp_p2 | C7: 410000 | D7: 2027-01-01 | H7: not_modeled | I7: =SUMIF($B$2:$B$150,"not_modeled",$C$2:$C$150) | K7: Anything the model should ignore (cars, collectibles, a business)
A8: Sam TFSA | B8: tfsa | C8: 118000 | D8: 2027-01-01
A9: Taylor TFSA | B9: tfsa | C9: 96000 | D9: 2027-01-01 | H9: One row per account, balance as of 1 January of the first year. cost_basis matters only for taxable accounts (blank = same as value, e.g. cash).
A10: Family RESP | B10: resp | C10: 88000 | D10: 2027-01-01
A11: Car | B11: not_modeled | C11: 25000 | D11: 2027-01-01

Sheet tax_tables
A1: Tax law used by the model (each spouse files separately; pension income is split). Yellow cells can be edited; indexed amounts grow with inflation after TAX_YEAR.
A2: Sources: CRA 2026 indexation (canada.ca, tax rates and payroll deduction tables); BC Budget 2026 (lowest rate 5.6%, indexing paused 2027-2030); ESDC CPP/OAS amounts (Jan 2026). Update each January.
A3: name | B3: value | C3: notes | E3: Federal brackets | I3: Provincial brackets: British Columbia | M3: RRIF minimum withdrawal (age on 1 January)
A4: TAX_YEAR | B4: 2026 | C4: Year the amounts on this tab are for; indexed amounts grow with inflation after it | E4: over | F4: rate | G4: step | I4: over | J4: rate | K4: step | M4: age | N4: minimum
A5: FED_CREDIT_RATE | B5: 0.14 | C5: Federal non-refundable credits are worth this rate (lowest bracket, 2026+) | E5: 0 | F5: 0.14 | G5: =IF(F5="",0,F5-0) | I5: 0 | J5: 0.056 | K5: =IF(J5="",0,J5-0) | M5: 71 | N5: 0.0528
A6: FED_BPA_MAX | B6: 16452 | C6: Federal basic personal amount (full) | E6: 58523 | F6: 0.205 | G6: =IF(F6="",0,F6-F5) | I6: 50363 | J6: 0.077 | K6: =IF(J6="",0,J6-J5) | M6: 72 | N6: 0.054
A7: FED_BPA_MIN | B7: 14829 | C7: ... reduced to this at high income | E7: 117045 | F7: 0.26 | G7: =IF(F7="",0,F7-F6) | I7: 100728 | J7: 0.105 | K7: =IF(J7="",0,J7-J6) | M7: 73 | N7: 0.0553
A8: FED_BPA_PHASE_START | B8: 181440 | C8: ... reduction starts at this net income | E8: 181440 | F8: 0.29 | G8: =IF(F8="",0,F8-F7) | I8: 115648 | J8: 0.1229 | K8: =IF(J8="",0,J8-J7) | M8: 74 | N8: 0.0567
A9: FED_BPA_PHASE_END | B9: 258482 | C9: ... and is complete here | E9: 258482 | F9: 0.33 | G9: =IF(F9="",0,F9-F8) | I9: 140430 | J9: 0.147 | K9: =IF(J9="",0,J9-J8) | M9: 75 | N9: 0.0582
A10: FED_AGE_AMOUNT | B10: 9208 | C10: Age amount (65+) | G10: =IF(F10="",0,F10-F9) | I10: 190405 | J10: 0.168 | K10: =IF(J10="",0,J10-J9) | M10: 76 | N10: 0.0598
A11: FED_AGE_THRESHOLD | B11: 46432 | C11: ... reduced by 15% of net income above this | G11: =IF(F11="",0,F11-F10) | I11: 265545 | J11: 0.205 | K11: =IF(J11="",0,J11-J10) | M11: 77 | N11: 0.0617
A12: AGE_REDUCTION_RATE | B12: 0.15 | G12: =IF(F12="",0,F12-F11) | K12: =IF(J12="",0,J12-J11) | M12: 78 | N12: 0.0636
A13: FED_PENSION_AMOUNT | B13: 2000 | C13: Pension income amount (not indexed) | G13: =IF(F13="",0,F13-F12) | K13: =IF(J13="",0,J13-J12) | M13: 79 | N13: 0.0658
A14: FED_EMPLOYMENT_AMOUNT | B14: 1501 | C14: Canada employment amount | G14: =IF(F14="",0,F14-F13) | K14: =IF(J14="",0,J14-J13) | M14: 80 | N14: 0.0682
A15: FED_MEDICAL_THRESHOLD | B15: 2891 | C15: Medical expenses above the lesser of 3% of net income and this | G15: =IF(F15="",0,F15-F14) | K15: =IF(J15="",0,J15-J14) | M15: 81 | N15: 0.0708
A16: FED_ELIGIBLE_DTC | B16: 0.150198 | C16: Federal dividend tax credit, eligible dividends (share of grossed-up amount) | G16: =IF(F16="",0,F16-F15) | K16: =IF(J16="",0,J16-J15) | M16: 82 | N16: 0.0738
A17: ELIGIBLE_GROSSUP | B17: 0.38 | C17: Eligible dividend gross-up | M17: 83 | N17: 0.0771
A18: CG_INCLUSION | B18: 0.5 | C18: Share of capital gains that is taxable | M18: 84 | N18: 0.0808
A19: OAS_MONTHLY | B19: 742.31 | C19: Full OAS pension at 65-74, per month (Jan 2026) | M19: 85 | N19: 0.0851
A20: OAS_75_BOOST | B20: 0.1 | C20: OAS increase from age 75 | M20: 86 | N20: 0.0899
A21: OAS_CLAWBACK_THRESHOLD | B21: 95323 | C21: OAS recovery tax starts at this net income | M21: 87 | N21: 0.0955
A22: OAS_CLAWBACK_RATE | B22: 0.15 | M22: 88 | N22: 0.1021
A23: CPP_MAX_MONTHLY | B23: 1507.65 | C23: Maximum CPP retirement pension at 65 (2026); caps survivor + own pension | M23: 89 | N23: 0.1099
A24: CPP_SURVIVOR_SHARE | B24: 0.6 | C24: Survivor pension (65+) as a share of the deceased's pension | M24: 90 | N24: 0.1192
A25: CPP_RATE | B25: 0.0595 | C25: Employee CPP contribution rate (base + first additional) | M25: 91 | N25: 0.1306
A26: CPP_EXEMPTION | B26: 3500 | C26: Basic exemption (not indexed) | M26: 92 | N26: 0.1449
A27: YMPE | B27: 74600 | C27: Year's maximum pensionable earnings | M27: 93 | N27: 0.1634
A28: CPP2_RATE | B28: 0.04 | C28: Second additional CPP rate | M28: 94 | N28: 0.1879
A29: YAMPE | B29: 85000 | C29: Year's additional maximum pensionable earnings | M29: 95 | N29: 0.2
A30: EI_RATE | B30: 0.0163 | C30: Employee EI premium rate | M30: 96 | N30: 0.2
A31: EI_MAX_INSURABLE | B31: 68900 | M31: 97 | N31: 0.2
A32: TFSA_LIMIT | B32: 7000 | C32: New TFSA room per person per year | M32: 98 | N32: 0.2
A33: PROV_NAME | B33: British Columbia | C33: Province used for provincial tax (edit the brackets and amounts to change it) | M33: 99 | N33: 0.2
A34: PROV_CREDIT_RATE | B34: 0.056 | C34: Provincial credits are worth this rate (BC lowest rate, 5.6% from 2026) | M34: 100 | N34: 0.2
A35: PROV_BPA | B35: 13216 | C35: Provincial basic personal amount | M35: 101 | N35: 0.2
A36: PROV_AGE_AMOUNT | B36: 5927 | C36: Provincial age amount (65+) | M36: 102 | N36: 0.2
A37: PROV_AGE_THRESHOLD | B37: 44119 | C37: ... reduced by 15% of net income above this | M37: 103 | N37: 0.2
A38: PROV_PENSION_AMOUNT | B38: 1000 | C38: Provincial pension income amount (not indexed) | M38: 104 | N38: 0.2
A39: PROV_MEDICAL_THRESHOLD | B39: 2748 | C39: Provincial medical expense threshold | M39: 105 | N39: 0.2
A40: PROV_ELIGIBLE_DTC | B40: 0.12 | C40: Provincial dividend tax credit, eligible dividends | M40: 106 | N40: 0.2
...

Sheet historical_returns
A1: year | B1: stocks | C1: bonds | D1: bills | E1: inflation | G1: US history: S&P 500 total return, 10-year Treasury, 3-month T-bill, CPI inflation. Source: Aswath Damodaran, NYU Stern (histretSP.xls, January 2026). Add a row each January, or replace the columns with another country's series (keep the headers).
A2: 1928 | B2: 0.438112 | C2: 0.008355 | D2: 0.0308 | E2: -0.011561
A3: 1929 | B3: -0.082979 | C3: 0.042038 | D3: 0.0316 | E3: 0.005848
A4: 1930 | B4: -0.251236 | C4: 0.045409 | D4: 0.0455 | E4: -0.063953
A5: 1931 | B5: -0.438375 | C5: -0.025589 | D5: 0.0231 | E5: -0.093168
A6: 1932 | B6: -0.086424 | C6: 0.087903 | D6: 0.0107 | E6: -0.10274
A7: 1933 | B7: 0.499822 | C7: 0.018553 | D7: 0.0096 | E7: 0.007634
A8: 1934 | B8: -0.011886 | C8: 0.079634 | D8: 0.002783 | E8: 0.015152
A9: 1935 | B9: 0.467404 | C9: 0.04472 | D9: 0.001675 | E9: 0.029851
A10: 1936 | B10: 0.319434 | C10: 0.050179 | D10: 0.001725 | E10: 0.014493
A11: 1937 | B11: -0.353367 | C11: 0.013791 | D11: 0.002758 | E11: 0.028571
A12: 1938 | B12: 0.292827 | C12: 0.042132 | D12: 0.00065 | E12: -0.027778
A13: 1939 | B13: -0.010976 | C13: 0.044123 | D13: 0.000458 | E13: 0
... A99: 2025 | B99: 0.177237 | C99: 0.077955 | D99: 0.0421 | E99: 0.027351

Sheet life_table
A1: age | B1: male_death_probability | C1: female_death_probability | E1: Probability of dying within a year at each age. US Social Security period life table for 2023 (as used in the 2026 Trustees Report). The Monte Carlo shifts it by the extra years of life expectancy set on the monte_carlo tab.
A2: 0 | B2: 0.006015 | C2: 0.005125
A3: 1 | B3: 0.000479 | C3: 0.000392
A4: 2 | B4: 0.00032 | C4: 0.000229
A5: 3 | B5: 0.000249 | C5: 0.000188
A6: 4 | B6: 0.000194 | C6: 0.000155
A7: 5 | B7: 0.000159 | C7: 0.000133
A8: 6 | B8: 0.000137 | C8: 0.000115
A9: 7 | B9: 0.000125 | C9: 0.000105
A10: 8 | B10: 0.00012 | C10: 0.0001
A11: 9 | B11: 0.00012 | C11: 9.8e-05
A12: 10 | B12: 0.000125 | C12: 0.000101
A13: 11 | B13: 0.00014 | C13: 0.000111
... A121: 119 | B121: 0.926604 | C121: 0.926604

Sheet monte_carlo
A1: Monte Carlo: every scenario replayed through history
A2: Each run replaces the Model tab's flat return and inflation with a stretch of real history (historical_returns tab) and draws lifetimes from the life_table tab. Change the yellow cells, then run the Monte Carlo (see README). Results are written below, in today's dollars.
A4: SETTINGS
A5: Stocks | B5: 0.6 | C5: Share of investments in stocks (historical_returns 'stocks' column)
A6: Bonds | B6: 0.4 | C6: Share in bonds ('bonds' column)
A7: Cash | B7: 0 | C7: Share in cash ('bills' column); the three should add to 100%
A8: Random runs per scenario | B8: 1000 | C8: 0 = historical starting years only
A9: Block length for random runs (years) | B9: 10 | C9: Random runs stitch together blocks of this many consecutive years of history
A10: Random seed | B10: 1 | C10: Change it to draw a different set of random runs
A11: Scenarios to run | C11: Comma-separated Model tab names; blank = every Model tab
A12: Sam: extra years of life expectancy | B12: 3 | C12: Years added to the life table's average. Healthier, higher-income people live longer (often +3 to +6). More years is the cautious direction
A13: Taylor: extra years of life expectancy | B13: 3 | C13: Same for person 2
A14: Survivor spending | B14: 0.7 | C14: After the first death, household and other spending as a share of the couple's
A15: Lifetimes drawn per historical start | B15: 20 | C15: Each historical start is run with this many random pairs of lifetimes
