Workbook

Sheet README
A1: Retirement plan
A2: A year-by-year retirement model for a couple, with a Monte Carlo test against history. See the project README for how to use it with Claude.
A4: Tabs
A5: Model - ...: a scenario. Yellow cells are its inputs (when you stop working, pensions, property sales, one-off events). Duplicate the tab to try another scenario.
A6: household: names, birth years, Social Security benefits, kids.
A7: budget: 12 months of spending by category (the statement pipeline fills it). The retirement_budget column is what the model spends.
A8: kids_budget: one line per kid and cost (support, college, help after college), each with its own years and amount.
A9: other_budget: renovations, cars and other big irregular costs, per year.
A10: properties: your home and any other properties.
A11: healthcare: marketplace, Medicare and long-term care costs.
A12: assets: every account, its balance and which bucket it feeds.
A13: tax_tables: the tax law the model uses (federal + your state). Edit to change state/province or update the law.
... A24: Not financial advice. Tax rules are simplified; check important decisions with a professional.

Sheet Model - Example
A1: Retirement model - Example
A2: Yellow cells are this scenario's inputs. To try another scenario: right-click this tab > Duplicate, rename it 'Model - <name>', change its yellow cells. Shared facts (budgets, properties, accounts, healthcare, tax law) are on the other tabs. Don't insert or delete rows on this tab.
A4: WORK | E4: RESULTS (today's dollars)
A5: =household!$B$5&"'s first year without a paycheck" | B5: 2030 | C5: The year after the last working year | E5: ="Net worth when "&household!$B$5&" is 70" | G5: =IFERROR(INDEX($J$92:$J$135,MATCH(household!$B$6+70,$A$92:$A$135,0)),"")
A6: =household!$B$8&"'s first year without a paycheck" | B6: 2029 | E6: ... at 80 | G6: =IFERROR(INDEX($J$92:$J$135,MATCH(household!$B$6+80,$A$92:$A$135,0)),"")
A7: =household!$B$5&"'s pay per year while working (today's $)" | B7: 190000 | C7: Salary + bonus + stock vesting | E7: ... at 85 | G7: =IFERROR(INDEX($J$92:$J$135,MATCH(household!$B$6+85,$A$92:$A$135,0)),"")
A8: =household!$B$8&"'s pay per year while working" | B8: 98000 | E8: ... at 90 | G8: =IFERROR(INDEX($J$92:$J$135,MATCH(household!$B$6+90,$A$92:$A$135,0)),"")
A9: =household!$B$5&"'s 401(k)/403(b) contributions (pre-tax)" | B9: 31000 | C9: While working | E9: ... at 95 | G9: =IFERROR(INDEX($J$92:$J$135,MATCH(household!$B$6+95,$A$92:$A$135,0)),"")
A10: =household!$B$8&"'s 401(k)/403(b) contributions (pre-tax)" | B10: 24500 | E10: ="Investments when "&household!$B$5&" is 90" | G10: =IFERROR(MAX(0,INDEX($I$92:$I$135,MATCH(household!$B$6+90,$A$92:$A$135,0))),"")
A11: ="Employer match / pension contributions for "&household!$B$5 | B11: 9500 | E11: First year investments can't cover costs | G11: =IF(COUNTIF($K$92:$K$135,">1")=0,"never",SUMPRODUCT(MIN($A$92:$A$135+($K$92:$K$135<=1)*10000)))
A12: ="Employer match / pension contributions for "&household!$B$8 | B12: 4900 | E12: First year's living costs | G12: =INDEX($D$92:$D$135,1)
A13: HSA contributions (while either works) | B13: 9550 | C13: Family limit + catch-up | E13: First year's withdrawal rate | G13: =INDEX($H$92:$H$135,1)
A14: Income tax withheld from pay | B14: 0.22 | C14: Share of taxable pay; the difference is settled next April | E14: Lifetime income tax (today's $) | G14: =SUMPRODUCT($EB$92:$EB$135/$O$92:$O$135)
A15: Tax owed for last year, paid in April of the first year | B15: 4000 | C15: Negative = a refund
A17: ECONOMY
A18: Inflation | B18: 0.03 | C18: Living costs, pay, pensions, tax brackets
A19: Investment return (per year, before inflation) | B19: 0.055 | C19: Override any year in the yellow 'Return override' column below
A20: Dividend yield on taxable accounts | B20: 0.015 | C20: Paid out as cash each year
A21: Healthcare cost growth | B21: =healthcare!$B$10 | C21: From the healthcare tab
A22: College cost growth | B22: 0.04
A23: Long-term care cost growth | B23: =healthcare!$B$12 | C23: From the healthcare tab
A25: SOCIAL SECURITY
A26: =household!$B$5&" starts Social Security at age" | B26: 68 | C26: 62-70
A27: =household!$B$8&" starts Social Security at age" | B27: 67 | C27: 62-70. A spouse can get up to half the other's benefit once both claim
A28: Benefit reduction for stopping work early | B28: 0.02 | C28: SSA statements assume you work until claiming; zero-earning years lower the average (often 1-5%)
A29: Across-the-board benefit cut | B29: 0.19 | C29: If Congress doesn't act, the trust fund pays ~81% from about 2034
A30: Cut starts in | B30: 2034 | C30: Set the cut to 0% to assume Congress fixes it
A31: =household!$B$5&"'s claim year" | B31: =household!$B$6+$B$26
A32: =household!$B$8&"'s claim year" | B32: =household!$B$9+$B$27
A33: =household!$B$5&"'s benefit vs full retirement age" | B33: =IF(ROUND(($B$26-tax_tables!$B$24)*12,0)>=0,1+0.08/12*MIN(ROUND(($B$26-tax_tables!$B$24)*12,0),36),1-5/900*MIN(-ROUND(($B$26-tax_tables!$B$24)*12,0),36)-5/1200*MAX(0,-ROUND(($B$26-tax_tables!$B$24)*12,0)-36)) | C33: Early claims are reduced, later ones get 8%/yr
A34: =household!$B$8&"'s benefit vs full retirement age" | B34: =IF(ROUND(($B$27-tax_tables!$B$24)*12,0)>=0,1+0.08/12*MIN(ROUND(($B$27-tax_tables!$B$24)*12,0),36),1-5/900*MIN(-ROUND(($B$27-tax_tables!$B$24)*12,0),36)-5/1200*MAX(0,-ROUND(($B$27-tax_tables!$B$24)*12,0)-36))
A35: =household!$B$5&"'s spousal benefit factor" | B35: =IF(ROUND(($B$26-tax_tables!$B$24)*12,0)>=0,1,1-25/3600*MIN(-ROUND(($B$26-tax_tables!$B$24)*12,0),36)-5/1200*MAX(0,-ROUND(($B$26-tax_tables!$B$24)*12,0)-36)) | C35: Spousal benefits don't grow after full retirement age
A36: =household!$B$8&"'s spousal benefit factor" | B36: =IF(ROUND(($B$27-tax_tables!$B$24)*12,0)>=0,1,1-25/3600*MIN(-ROUND(($B$27-tax_tables!$B$24)*12,0),36)-5/1200*MAX(0,-ROUND(($B$27-tax_tables!$B$24)*12,0)-36))
A38: WHERE YOU LIVE (STATE TAX)
A39: Year you move to another state | C39: Blank = stay. The state brackets are on the tax_tables tab
A40: The new state's income tax rate | B40: 0 | C40: Flat rate on income except Social Security; 0% for FL, TX, TN, NV, WA...
A42: WORKPLACE PENSIONS
A43: =household!$B$5&"'s defined-benefit pension per year (today's $)" | B43: 0 | C43: 0 = none. Your pension statement's estimate
A44: ... starts at age | B44: 65
A45: =household!$B$8&"'s defined-benefit pension per year (today's $)" | B45: 26000
...

Sheet household
A1: key | B1: value | C1: notes
A2: country | B2: US | C2: US = United States, CA = Canada. Fixed when the workbook is built
A3: region | B3: New York | C3: State or province (its tax brackets are on the tax_tables tab)
A4: start_year | B4: 2027 | C4: First year the model covers. Balances on the assets tab are as of 1 January of it; 'today's dollars' are the year before
A5: p1_name | B5: Alex | C5: Person 1
A6: p1_born | B6: 1968 | C6: Birth year
A7: p1_sex | B7: F | C7: M or F: which column of the life table the Monte Carlo uses for person 1
A8: p2_name | B8: Jordan | C8: Person 2
A9: p2_born | B9: 1970 | C9: Birth year
A10: p2_sex | B10: M | C10: M or F for person 2
A11: p1_ss_benefit | B11: 3650 | C11: Person 1's Social Security at full retirement age (67), per month, today's $ - from ssa.gov/myaccount
A12: p2_ss_benefit | B12: 2380 | C12: Person 2's, on their own record
A14: Kids
A15: name | B15: born | C15: on_health_plan_through | D15: notes
A16: Riley | B16: 2006 | C16: 2032 | D16: Stays on the family plan until 26 (or a first job with benefits)
A17: Casey | B17: 2009 | C17: 2035
A24: Kids' costs are on the kids_budget tab (one line per kid and cost). Health-plan years matter once you buy your own coverage.

Sheet budget
A1: model_line | B1: expense_group | C1: category | D1: subcategory | E1: annual_actual | F1: retirement_budget | G1: source_period | H1: n_transactions | I1: notes | K1: Household living budget used by the model | L1: =SUMIF($A$2:$A$300,"household",$F$2:$F$300)
A2: household | B2: Essential | C2: Groceries | D2: General | E2: 15840 | F2: 15840 | G2: example | H2: 212 | K2: All lines, 12-month actual | L2: =SUM($E$2:$E$300)
A3: household | B3: Essential | C3: Utilities | D3: Electric, gas, water | E3: 4320 | F3: 4320 | G3: example | H3: 24
A4: household | B4: Essential | C4: Utilities | D4: Phone & internet | E4: 2760 | F4: 2760 | G4: example | H4: 24 | K4: model_line: 'household' lines are summed and grow with inflation. Other lines (housing, healthcare, taxes, kids) are modeled on their own tabs and shown here only for reference.
A5: household | B5: Essential | C5: Insurance | D5: General | E5: 4150 | F5: 4150 | G5: example | H5: 6 | K5: Edit column F (retirement_budget) to test a different budget; column E is what you actually spent.
A6: household | B6: Essential | C6: Transportation | D6: Gas & parking | E6: 3600 | F6: 3600 | G6: example | H6: 96
A7: household | B7: Essential | C7: Transportation | D7: Car maintenance | E7: 1900 | F7: 1900 | G7: example | H7: 5
A8: household | B8: Essential | C8: Personal Care | D8: General | E8: 2100 | F8: 2100 | G8: example | H8: 30
A9: household | B9: Discretionary | C9: Dining | D9: Restaurants & takeout | E9: 9800 | F9: 9800 | G9: example | H9: 180
A10: household | B10: Discretionary | C10: Travel | D10: Flights, hotels, rentals | E10: 14500 | F10: 16000 | G10: example | H10: 40 | I10: Planning to travel a bit more once retired
A11: household | B11: Discretionary | C11: Shopping | D11: General | E11: 11200 | F11: 10000 | G11: example | H11: 260
A12: household | B12: Discretionary | C12: Entertainment | D12: General | E12: 3400 | F12: 3400 | G12: example | H12: 45
A13: household | B13: Discretionary | C13: Subscriptions | D13: Streaming & software | E13: 1250 | F13: 1250 | G13: example | H13: 48
A14: household | B14: Discretionary | C14: Gifts & Donations | D14: General | E14: 5200 | F14: 5200 | G14: example | H14: 22
A15: household | B15: Discretionary | C15: Home | D15: Household goods | E15: 3100 | F15: 3100 | G15: example | H15: 55
A16: household | B16: Discretionary | C16: Pets | D16: General | E16: 2400 | F16: 2400 | G16: example | H16: 30
A17: household | B17: Discretionary | C17: Cash | D17: Withdrawals | E17: 1800 | F17: 1800 | G17: example | H17: 20
A18: housing | B18: Housing | C18: Housing | D18: Mortgage | E18: 22140 | G18: example | H18: 12 | I18: Modeled from the properties tab (mortgage balance and payment)
A19: housing | B19: Housing | C19: Housing | D19: Property tax & insurance | E19: 13900 | G19: example | H19: 6 | I19: Modeled from the properties tab (carrying_costs)
A20: healthcare | B20: Healthcare | C20: Healthcare | D20: Out-of-pocket | E20: 3800 | G20: example | H20: 40 | I20: Modeled on the healthcare tab
A21: kids | B21: Kids | C21: Kids | D21: Support | E21: 19200 | G21: example | H21: 48 | I21: Modeled on the kids_budget tab
A22: taxes | B22: Taxes | C22: Taxes | D22: Estimated payments | E22: 8000 | G22: example | H22: 4 | I22: Replaced by the model's own tax calculation

Sheet kids_budget
A1: kid | B1: item | C1: annual_amount_today | D1: start_year | E1: end_year | F1: inflation | G1: paid_from | H1: notes
A2: Riley | B2: College (private) - tuition + room and board | C2: 82000 | D2: 2027 | E2: 2028 | F2: college | G2: college_funds | H2: Junior and senior years; 529 pays first
A3: Riley | B3: Spending money in college | C3: 6000 | D3: 2027 | E3: 2028 | F3: general | G3: parents
A4: Riley | B4: Help after college (rent share + phone + insurance) | C4: 14000 | D4: 2029 | E4: 2031 | F4: general | G4: parents | H4: First three years after graduating
A5: Riley | B5: Wedding gift | C5: 30000 | D5: 2033 | E5: 2033 | F5: general | G5: parents | H5: A one-time line: start = end year
A6: Casey | B6: College (state school) - tuition + room and board | C6: 34000 | D6: 2027 | E6: 2031 | F6: college | G6: college_funds | H6: Five-year program
A7: Casey | B7: Spending money in college | C7: 5000 | D7: 2027 | E7: 2031 | F7: general | G7: parents
A8: Casey | B8: Help after college | C8: 20000 | D8: 2032 | E8: 2033 | F8: general | G8: parents | H8: Two years while in grad school
A42: One line per kid and cost, per year in today's dollars, for the years start_year-end_year. inflation: 'college' lines rise with college cost growth, 'general' with inflation. paid_from: 'college_funds' lines are paid by the 529s first and only the shortfall comes from you; 'parents' lines come straight from you. Add rows above row 41.

Sheet other_budget
A1: item | B1: annual_amount_today | C1: start_year | D1: end_year | E1: notes
A2: Home repairs and renovations | B2: 12000 | C2: 2027 | D2: 2060 | E2: About 2% of the home's value a year
A3: Car replacement | B3: 8000 | C3: 2027 | D3: 2055 | E3: A $40k car every five years
A4: Help for aging parents | B4: 6000 | C4: 2027 | D4: 2032
A32: Big irregular costs averaged per year (renovations, cars, gifts), in today's dollars, for the years start_year-end_year. Add rows above row 31.

Sheet properties
A1: property | B1: type | C1: value_now | D1: appreciation | E1: selling_cost_pct | F1: cost_basis | G1: carrying_costs | H1: property_tax | I1: mortgage_balance | J1: mortgage_rate | K1: mortgage_payment | L1: rent | M1: cash_costs | N1: depreciation | O1: depreciation_end_year | P1: accum_depreciation | Q1: notes
A2: Home (Saratoga Springs) | B2: primary | C2: 640000 | D2: 0.03 | E2: 0.07 | F2: 410000 | G2: 15600 | H2: 11200 | I2: 262000 | J2: 0.0325 | K2: 22140 | Q2: Bought 2012 for $380,000 + $30,000 kitchen. Carrying costs: property tax $11,200, insurance $2,400, other $2,000
A3: Condo rental (Albany) | B3: rental | C3: 310000 | D3: 0.025 | E3: 0.07 | F3: 245000 | L3: 25200 | M3: 10400 | N3: 7100 | O3: 2045 | P3: 63900 | Q3: Bought 2018 for $245,000 ($50,000 land). Cash costs: HOA $4,800, tax $3,900, insurance $900, repairs $800
A9: Row 2 is your home (principal residence); rows 3-6 are other properties (rentals, a cottage). Sell / rent decisions are made on each Model tab. Amounts are today's dollars.
A10: value_now: market value; appreciation: growth per year. carrying_costs: property tax + condo/HOA/strata fees + insurance + utilities you want counted as housing (for the home; if you rent, put the rent here and leave value_now blank). property_tax: the part that's property tax (deductible up to the SALT cap).
A11: mortgage_*: the home's mortgage on 1 January of the first year (balance, interest rate, payments per year). Other properties are assumed mortgage-free: include any loan payments in cash_costs.
A12: Other properties: rent and cash_costs per year; depreciation claimed per year until depreciation_end_year, and accum_depreciation already claimed. cost_basis is what you paid plus improvements.

Sheet healthcare
A1: key | B1: value | C1: unit | D1: notes | E1: source
A2: marketplace_adult_monthly | B2: 1150 | C2: $/month | D2: Unsubsidized Silver plan for a ~60-year-old. Check healthcare.gov or your state exchange; prices vary a lot by state and age (NY doesn't rate by age) | E2: healthcare.gov plan finder
A3: marketplace_child_monthly | B3: 450 | C3: $/month | D3: Per child on your plan | E3: healthcare.gov plan finder
A4: marketplace_oop_per_person | B4: 3000 | C4: $/year | D4: Deductibles and copays on a Silver plan
A5: employer_plan_cost | B5: 9000 | C5: $/year | D5: Your share of premiums + out-of-pocket while working (the model uses it while either of you works) | E5: Pay stubs / benefits portal
A6: medicare_part_b_monthly | B6: 202.9 | C6: $/month | D6: 2026 standard Part B premium | E6: CMS
A7: medicare_part_d_monthly | B7: 45 | C7: $/month | D7: Typical Part D plan | E7: medicare.gov plan finder
A8: medigap_monthly | B8: 250 | C8: $/month | D8: Medigap Plan G around 65-70 | E8: medicare.gov plan finder
A9: medicare_oop_per_person | B9: 1500 | C9: $/year | D9: Part B deductible, dental, vision, hearing
A10: medical_inflation | B10: 0.05 | C10: per year | D10: Healthcare costs have grown ~2 points faster than inflation
A11: ltc_annual_cost | B11: 130000 | C11: $/year | D11: Home health aide or assisted living; a nursing home is ~$120-180k in the Northeast | E11: Genworth / CareScout cost of care survey
A12: ltc_inflation | B12: 0.04 | C12: per year

Sheet assets
A1: account | B1: bucket | C1: value | D1: as_of | E1: cost_basis | F1: notes | H1: bucket | I1: total | J1: cost basis | K1: what goes in it
A2: Brokerage (joint) - index funds | B2: taxable | C2: 880000 | D2: 2027-01-01 | E2: 560000 | H2: taxable | I2: =SUMIF($B$2:$B$150,"taxable",$C$2:$C$150) | J2: =SUMIF($B$2:$B$150,"taxable",$E$2:$E$150) | K2: Taxable brokerage accounts, bank and money-market cash
A3: High-yield savings | B3: taxable | C3: 55000 | D3: 2027-01-01 | F3: cash: cost basis = value | H3: pretax_p1 | I3: =SUMIF($B$2:$B$150,"pretax_p1",$C$2:$C$150) | K3: Person 1's 401(k), 403(b), traditional IRA, other pre-tax accounts
A4: Checking | B4: taxable | C4: 15000 | D4: 2027-01-01 | H4: pretax_p2 | I4: =SUMIF($B$2:$B$150,"pretax_p2",$C$2:$C$150) | K4: Person 2's pre-tax accounts
A5: Alex 401(k) | B5: pretax_p1 | C5: 1150000 | D5: 2027-01-01 | H5: roth | I5: =SUMIF($B$2:$B$150,"roth",$C$2:$C$150) | K5: Roth IRAs and Roth 401(k)s (either person)
A6: Alex rollover IRA | B6: pretax_p1 | C6: 210000 | D6: 2027-01-01 | H6: hsa | I6: =SUMIF($B$2:$B$150,"hsa",$C$2:$C$150) | K6: Health savings accounts
A7: Jordan 403(b) | B7: pretax_p2 | C7: 540000 | D7: 2027-01-01 | H7: college_529 | I7: =SUMIF($B$2:$B$150,"college_529",$C$2:$C$150) | K7: 529 plans and other money set aside for the kids' college (not counted as yours)
A8: Alex Roth IRA | B8: roth | C8: 95000 | D8: 2027-01-01 | H8: not_modeled | I8: =SUMIF($B$2:$B$150,"not_modeled",$C$2:$C$150) | K8: Anything the model should ignore (cars, collectibles, a business)
A9: Jordan Roth IRA | B9: roth | C9: 62000 | D9: 2027-01-01
A10: HSA | B10: hsa | C10: 48000 | D10: 2027-01-01 | H10: One row per account, balance as of 1 January of the first year. cost_basis matters only for taxable accounts (blank = same as value, e.g. cash).
A11: Riley 529 | B11: college_529 | C11: 115000 | D11: 2027-01-01
A12: Casey 529 | B12: college_529 | C12: 130000 | D12: 2027-01-01
A13: Cars | B13: not_modeled | C13: 35000 | D13: 2027-01-01 | F13: Not investments

Sheet tax_tables
A1: Tax law used by the model (married filing jointly). Yellow cells can be edited; indexed amounts grow with inflation after TAX_YEAR.
A2: Sources: IRS Rev. Proc. 2025-32 (2026 amounts, One Big Beautiful Bill Act); SSA and CMS 2026 figures; state brackets from the state's tax department. Update each January.
A3: name | B3: value | C3: notes | E3: Federal ordinary brackets (joint) | I3: Federal capital gains / qualified dividends (joint) | M3: State brackets (joint): New York | Q3: Medicare IRMAA (per person per month) | V3: SALT cap by year | Y3: Uniform Lifetime Table (RMDs)
A4: TAX_YEAR | B4: 2026 | C4: Year the amounts on this tab are for; indexed amounts grow with inflation after it | E4: over | F4: rate | G4: step | I4: over | J4: rate | K4: step | M4: over | N4: rate | O4: step | Q4: MAGI over | R4: Part B add-on | S4: Part D add-on | T4: step | V4: year | W4: cap | Y4: age | Z4: factor
A5: FED_STD | B5: 32200 | C5: Standard deduction, married filing jointly | E5: 0 | F5: 0.1 | G5: =IF(F5="",0,F5-0) | I5: 0 | J5: 0 | K5: =IF(J5="",0,J5-0) | M5: 0 | N5: 0.04 | O5: =IF(N5="",0,N5-0) | Q5: 218000 | R5: 81.2 | S5: 14.5 | T5: =R5+S5 | V5: 2026 | W5: 40400 | Y5: 72 | Z5: 27.4
A6: FED_65_ADD | B6: 1650 | C6: Extra standard deduction per spouse 65+ | E6: 24800 | F6: 0.12 | G6: =IF(F6="",0,F6-F5) | I6: 98900 | J6: 0.15 | K6: =IF(J6="",0,J6-J5) | M6: 17150 | N6: 0.045 | O6: =IF(N6="",0,N6-N5) | Q6: 274000 | R6: 202.9 | S6: 37.5 | T6: =R6+S6-R5-S5 | V6: 2027 | W6: 40804 | Y6: 73 | Z6: 26.5
A7: SENIOR_DED | B7: 6000 | C7: OBBBA senior deduction per person 65+ (not indexed) | E7: 100800 | F7: 0.22 | G7: =IF(F7="",0,F7-F6) | I7: 613700 | J7: 0.2 | K7: =IF(J7="",0,J7-J6) | M7: 23600 | N7: 0.0525 | O7: =IF(N7="",0,N7-N6) | Q7: 342000 | R7: 324.6 | S7: 60.4 | T7: =R7+S7-R6-S6 | V7: 2028 | W7: 41212 | Y7: 74 | Z7: 25.5
A8: SENIOR_DED_FROM | B8: 2025 | C8: ... first year | E8: 211400 | F8: 0.24 | G8: =IF(F8="",0,F8-F7) | K8: =IF(J8="",0,J8-J7) | M8: 27900 | N8: 0.055 | O8: =IF(N8="",0,N8-N7) | Q8: 410000 | R8: 446.3 | S8: 83.3 | T8: =R8+S8-R7-S7 | V8: 2029 | W8: 41624 | Y8: 75 | Z8: 24.6
A9: SENIOR_DED_TO | B9: 2028 | C9: ... last year (expires after 2028 under current law) | E9: 403550 | F9: 0.32 | G9: =IF(F9="",0,F9-F8) | K9: =IF(J9="",0,J9-J8) | M9: 161550 | N9: 0.06 | O9: =IF(N9="",0,N9-N8) | Q9: 750000 | R9: 487 | S9: 91 | T9: =R9+S9-R8-S8 | Y9: 76 | Z9: 23.7
A10: SENIOR_PHASEOUT_START | B10: 150000 | C10: ... reduced by 6% of MAGI above this (joint) | E10: 512450 | F10: 0.35 | G10: =IF(F10="",0,F10-F9) | K10: =IF(J10="",0,J10-J9) | M10: 323200 | N10: 0.0685 | O10: =IF(N10="",0,N10-N9) | Y10: 77 | Z10: 22.9
A11: SENIOR_PHASEOUT_RATE | B11: 0.06 | E11: 768700 | F11: 0.37 | G11: =IF(F11="",0,F11-F10) | K11: =IF(J11="",0,J11-J10) | M11: 2155350 | N11: 0.0965 | O11: =IF(N11="",0,N11-N10) | Y11: 78 | Z11: 22
A12: NIIT_RATE | B12: 0.038 | C12: Net investment income tax | G12: =IF(F12="",0,F12-F11) | K12: =IF(J12="",0,J12-J11) | M12: 5000000 | N12: 0.103 | O12: =IF(N12="",0,N12-N11) | Y12: 79 | Z12: 21.1
A13: NIIT_THRESHOLD | B13: 250000 | C13: Not indexed | G13: =IF(F13="",0,F13-F12) | K13: =IF(J13="",0,J13-J12) | M13: 25000000 | N13: 0.109 | O13: =IF(N13="",0,N13-N12) | Y13: 80 | Z13: 20.2
A14: SS_TAXABLE_BASE | B14: 32000 | C14: Social Security taxation thresholds (joint, not indexed) | G14: =IF(F14="",0,F14-F13) | K14: =IF(J14="",0,J14-J13) | O14: =IF(N14="",0,N14-N13) | Y14: 81 | Z14: 19.4
A15: SS_TAXABLE_ADJUSTED_BASE | B15: 44000 | G15: =IF(F15="",0,F15-F14) | K15: =IF(J15="",0,J15-J14) | O15: =IF(N15="",0,N15-N14) | Y15: 82 | Z15: 18.5
A16: SALT_CAP_AFTER | B16: 10000 | C16: SALT cap after the years in the SALT table | G16: =IF(F16="",0,F16-F15) | K16: =IF(J16="",0,J16-J15) | O16: =IF(N16="",0,N16-N15) | Y16: 83 | Z16: 17.7
A17: SALT_PHASEDOWN_START | B17: 505000 | C17: SALT cap phase-down starts at this MAGI (2026; grows 1%/yr through 2029) | Y17: 84 | Z17: 16.8
A18: SALT_PHASEDOWN_RATE | B18: 0.3 | Y18: 85 | Z18: 16
A19: UNRECAPTURED_1250_EXTRA | B19: 0.1 | C19: Depreciation recapture: 25% max rate vs 15% | Y19: 86 | Z19: 15.2
A20: HOME_SALE_EXCLUSION | B20: 500000 | C20: Gain excluded on selling your home (joint) | Y20: 87 | Z20: 14.4
A21: SS_WAGE_BASE | B21: 184500 | C21: Social Security payroll tax wage base | Y21: 88 | Z21: 13.7
A22: ADDITIONAL_MEDICARE_THRESHOLD | B22: 250000 | C22: 0.9% extra Medicare tax above this (joint, not indexed) | Y22: 89 | Z22: 12.9
A23: MEDICAL_FLOOR | B23: 0.075 | C23: Medical expenses deductible above this share of AGI | Y23: 90 | Z23: 12.2
A24: SS_FULL_RETIREMENT_AGE | B24: 67 | C24: Born 1960 or later | Y24: 91 | Z24: 11.5
A25: STATE_NAME | B25: New York | C25: State used for state income tax (edit the brackets below to change it) | Y25: 92 | Z25: 10.8
A26: STATE_STD | B26: 16050 | C26: State standard deduction (joint) | Y26: 93 | Z26: 10.1
A27: STATE_INDEXED | B27: 0 | C27: 1 = state brackets and deduction grow with inflation; 0 = fixed | Y27: 94 | Z27: 9.5
A28: STATE_SS_EXEMPT | B28: 1 | C28: 1 = state doesn't tax Social Security | Y28: 95 | Z28: 8.9
A29: STATE_RET_EXCLUSION | B29: 20000 | C29: Per-person exclusion for IRA/401(k)/pension withdrawals | Y29: 96 | Z29: 8.4
A30: STATE_RET_EXCLUSION_AGE | B30: 59.5 | C30: ... from this age | Y30: 97 | Z30: 7.8
A31: LOCAL_RATE | B31: 0 | C31: Flat city/county income tax on state taxable income (NYC is roughly 0.039) | Y31: 98 | Z31: 7.3
Y32: 99 | Z32: 6.8
Y33: 100 | Z33: 6.4
Y34: 101 | Z34: 6
Y35: 102 | Z35: 5.6
Y36: 103 | Z36: 5.2
Y37: 104 | Z37: 4.9
Y38: 105 | Z38: 4.6
Y39: 106 | Z39: 4.3
Y40: 107 | Z40: 4.1
...

Sheet historical_returns
A1: year | B1: stocks | C1: bonds | D1: bills | E1: inflation | G1: US history: S&P 500 total return, 10-year Treasury, 3-month T-bill, CPI inflation. Source: Aswath Damodaran, NYU Stern (histretSP.xls, January 2026). Add a row each January, or replace the columns with another country's series (keep the headers).
A2: 1928 | B2: 0.438112 | C2: 0.008355 | D2: 0.0308 | E2: -0.011561
A3: 1929 | B3: -0.082979 | C3: 0.042038 | D3: 0.0316 | E3: 0.005848
A4: 1930 | B4: -0.251236 | C4: 0.045409 | D4: 0.0455 | E4: -0.063953
A5: 1931 | B5: -0.438375 | C5: -0.025589 | D5: 0.0231 | E5: -0.093168
A6: 1932 | B6: -0.086424 | C6: 0.087903 | D6: 0.0107 | E6: -0.10274
A7: 1933 | B7: 0.499822 | C7: 0.018553 | D7: 0.0096 | E7: 0.007634
A8: 1934 | B8: -0.011886 | C8: 0.079634 | D8: 0.002783 | E8: 0.015152
A9: 1935 | B9: 0.467404 | C9: 0.04472 | D9: 0.001675 | E9: 0.029851
A10: 1936 | B10: 0.319434 | C10: 0.050179 | D10: 0.001725 | E10: 0.014493
A11: 1937 | B11: -0.353367 | C11: 0.013791 | D11: 0.002758 | E11: 0.028571
A12: 1938 | B12: 0.292827 | C12: 0.042132 | D12: 0.00065 | E12: -0.027778
A13: 1939 | B13: -0.010976 | C13: 0.044123 | D13: 0.000458 | E13: 0
... A99: 2025 | B99: 0.177237 | C99: 0.077955 | D99: 0.0421 | E99: 0.027351

Sheet life_table
A1: age | B1: male_death_probability | C1: female_death_probability | E1: Probability of dying within a year at each age. US Social Security period life table for 2023 (as used in the 2026 Trustees Report). The Monte Carlo shifts it by the extra years of life expectancy set on the monte_carlo tab.
A2: 0 | B2: 0.006015 | C2: 0.005125
A3: 1 | B3: 0.000479 | C3: 0.000392
A4: 2 | B4: 0.00032 | C4: 0.000229
A5: 3 | B5: 0.000249 | C5: 0.000188
A6: 4 | B6: 0.000194 | C6: 0.000155
A7: 5 | B7: 0.000159 | C7: 0.000133
A8: 6 | B8: 0.000137 | C8: 0.000115
A9: 7 | B9: 0.000125 | C9: 0.000105
A10: 8 | B10: 0.00012 | C10: 0.0001
A11: 9 | B11: 0.00012 | C11: 9.8e-05
A12: 10 | B12: 0.000125 | C12: 0.000101
A13: 11 | B13: 0.00014 | C13: 0.000111
... A121: 119 | B121: 0.926604 | C121: 0.926604

Sheet monte_carlo
A1: Monte Carlo: every scenario replayed through history
A2: Each run replaces the Model tab's flat return and inflation with a stretch of real history (historical_returns tab) and draws lifetimes from the life_table tab. Change the yellow cells, then run the Monte Carlo (see README). Results are written below, in today's dollars.
A4: SETTINGS
A5: Stocks | B5: 0.6 | C5: Share of investments in stocks (historical_returns 'stocks' column)
A6: Bonds | B6: 0.4 | C6: Share in bonds ('bonds' column)
A7: Cash | B7: 0 | C7: Share in cash ('bills' column); the three should add to 100%
A8: Random runs per scenario | B8: 1000 | C8: 0 = historical starting years only
A9: Block length for random runs (years) | B9: 10 | C9: Random runs stitch together blocks of this many consecutive years of history
A10: Random seed | B10: 1 | C10: Change it to draw a different set of random runs
A11: Scenarios to run | C11: Comma-separated Model tab names; blank = every Model tab
A12: Alex: extra years of life expectancy | B12: 3 | C12: Years added to the life table's average. Healthier, higher-income people live longer (often +3 to +6). More years is the cautious direction
A13: Jordan: extra years of life expectancy | B13: 3 | C13: Same for person 2
A14: Survivor spending | B14: 0.7 | C14: After the first death, household and other spending as a share of the couple's
A15: Lifetimes drawn per historical start | B15: 20 | C15: Each historical start is run with this many random pairs of lifetimes
